Workbook

Sheet Sheet1
C1: Cost | D1: Qty | E1: Per sensor
B2: TcA Sensor | C2: 7527 | D2: 1 | E2: =+C2*D2 -> 7527 | K2: Glue | L2: 10 | M2: senors
B3: HF+2 Sensor | C3: 10934 | D3: 1 | E3: =+C3*D3 -> 10934 | F3: High Speed | K3: Nozzles | L3: =4*72 -> 288 | M3: sensors
B4: Gateway | C4: 20480 | D4: 1 | E4: =+C4*D4 -> 20480 | K4: Initial setup | L4: Softwa
B5: Steel base (1 / sensor) | C5: 130 | D5: 1 | E5: =+C5*D5 -> 130 | K5: Installation per day ( 2 people, 20-25 sensors per day) | L5: 15295
B6: Spacer (1 per sensor) | C6: 285 | D6: 1 | E6: =+C6*D6 -> 285 | K6: Travel | L6: 18988
B7: Glue (1 tube =10 sensors) | C7: 5600 | D7: 0.1 | E7: =+C7*D7 -> 560 | K7: Accommodation / day | L7: 2200
B8: Nozzle Box | C8: 2952 | D8: =1/288 -> 0.0034722222 | E8: =+C8*D8 -> 10.25 | K8: Gateway - 100 sensors
B10: Initial setup | C10: 9600 | K10: Motors en Ratkaste
B11: Travel | C11: 16512 | E11: Days | K11: Pulleys
B12: Accommodation / day | C12: 2200 | E12: Days
B13: Installation per day (2 people) | C13: 13300 | E13: Days | F13: 20-25 sensors per day | K13: power supply = 220V
K15: Alarms en trends. Can get free excess. No license fees. No yearly fees.
K16: Monitoring sevrice = once off cost. + R3.8k per sensor per year
K17: Users. Unlimited

Sheet Sheet1 (2)
B1: N2 | F1: # Pulleys | G1: # Sensors | H1: # Gateways | I1: Sensor cost | J1: Base & Spacer | K1: Consumables | L1: Gateway | M1: # Days | N1: Labour Cost | O1: Accommodation | P1: Total Parts & Labour
B2: Crusher feed belt at 2W plant | F2: 4 | G2: =F2*2 -> 8 | H2: 1 | I2: =+G2*Sheet1!$E$2 -> 60216 | J2: =+(Sheet1!$E$5+Sheet1!$E$6)*G2 -> 3320 | K2: =+(Sheet1!$E$7+Sheet1!$E$8)*G2 -> 4562 | L2: =+Sheet1!$E$4*H2 -> 20480 | M2: 2 | N2: =+M2*Sheet1!$C$13 -> 26600 | O2: =+M2*Sheet1!$C$12 -> 4400 | P2: =+N2+L2+K2+J2+I2 -> 115178
B3: Orepass feed belt andd | F3: 16 | G3: =F3*2 -> 32 | H3: 2 | I3: =+G3*Sheet1!$E$2 -> 240864 | J3: =+(Sheet1!$E$5+Sheet1!$E$6)*G3 -> 13280 | K3: =+(Sheet1!$E$7+Sheet1!$E$8)*G3 -> 18248 | L3: =+Sheet1!$E$4*H3 -> 40960 | M3: 3 | N3: =+M3*Sheet1!$C$13 -> 39900 | O3: =+M3*Sheet1!$C$12 -> 6600 | P3: =+N3+L3+K3+J3+I3 -> 353252
B4: NR1 conveyor | F4: =+G4/2 -> 2 | G4: 4 | H4: 1 | I4: =+G4*Sheet1!$E$2 -> 30108 | J4: =+(Sheet1!$E$5+Sheet1!$E$6)*G4 -> 1660 | K4: =+(Sheet1!$E$7+Sheet1!$E$8)*G4 -> 2281 | L4: =+Sheet1!$E$4*H4 -> 20480 | M4: 4 | N4: =+M4*Sheet1!$C$13 -> 53200 | O4: =+M4*Sheet1!$C$12 -> 8800 | P4: =+N4+L4+K4+J4+I4 -> 107729
B5: NR2 conveyor | F5: =+G5/2 -> 7 | G5: 14 | H5: 1 | I5: =+G5*Sheet1!$E$2 -> 105378 | J5: =+(Sheet1!$E$5+Sheet1!$E$6)*G5 -> 5810 | K5: =+(Sheet1!$E$7+Sheet1!$E$8)*G5 -> 7983.5 | L5: =+Sheet1!$E$4*H5 -> 20480 | M5: 5 | N5: =+M5*Sheet1!$C$13 -> 66500 | O5: =+M5*Sheet1!$C$12 -> 11000 | P5: =+N5+L5+K5+J5+I5 -> 206151.5
B6: NR3 conveyor | F6: =+G6/2 -> 12 | G6: 24 | H6: 2 | I6: =+G6*Sheet1!$E$2 -> 180648 | J6: =+(Sheet1!$E$5+Sheet1!$E$6)*G6 -> 9960 | K6: =+(Sheet1!$E$7+Sheet1!$E$8)*G6 -> 13686 | L6: =+Sheet1!$E$4*H6 -> 40960 | M6: 6 | N6: =+M6*Sheet1!$C$13 -> 79800 | O6: =+M6*Sheet1!$C$12 -> 13200 | P6: =+N6+L6+K6+J6+I6 -> 325054
B7: NR4 conveyor | F7: =+G7/2 -> 7 | G7: 14 | H7: 1 | I7: =+G7*Sheet1!$E$2 -> 105378 | J7: =+(Sheet1!$E$5+Sheet1!$E$6)*G7 -> 5810 | K7: =+(Sheet1!$E$7+Sheet1!$E$8)*G7 -> 7983.5 | L7: =+Sheet1!$E$4*H7 -> 20480 | M7: 7 | N7: =+M7*Sheet1!$C$13 -> 93100 | O7: =+M7*Sheet1!$C$12 -> 15400 | P7: =+N7+L7+K7+J7+I7 -> 232751.5
B8: NR5 conveyor | F8: =+G8/2 -> 7 | G8: 14 | H8: 1 | I8: =+G8*Sheet1!$E$2 -> 105378 | J8: =+(Sheet1!$E$5+Sheet1!$E$6)*G8 -> 5810 | K8: =+(Sheet1!$E$7+Sheet1!$E$8)*G8 -> 7983.5 | L8: =+Sheet1!$E$4*H8 -> 20480 | M8: 8 | N8: =+M8*Sheet1!$C$13 -> 106400 | O8: =+M8*Sheet1!$C$12 -> 17600 | P8: =+N8+L8+K8+J8+I8 -> 246051.5
B9: NR6 conveyor | F9: =+G9/2 -> 7 | G9: 14 | H9: 1 | I9: =+G9*Sheet1!$E$2 -> 105378 | J9: =+(Sheet1!$E$5+Sheet1!$E$6)*G9 -> 5810 | K9: =+(Sheet1!$E$7+Sheet1!$E$8)*G9 -> 7983.5 | L9: =+Sheet1!$E$4*H9 -> 20480 | M9: 9 | N9: =+M9*Sheet1!$C$13 -> 119700 | O9: =+M9*Sheet1!$C$12 -> 19800 | P9: =+N9+L9+K9+J9+I9 -> 259351.5
B10: NR7 conveyor | F10: =+G10/2 -> 7 | G10: 14 | H10: 1 | I10: =+G10*Sheet1!$E$2 -> 105378 | J10: =+(Sheet1!$E$5+Sheet1!$E$6)*G10 -> 5810 | K10: =+(Sheet1!$E$7+Sheet1!$E$8)*G10 -> 7983.5 | L10: =+Sheet1!$E$4*H10 -> 20480 | M10: 10 | N10: =+M10*Sheet1!$C$13 -> 133000 | O10: =+M10*Sheet1!$C$12 -> 22000 | P10: =+N10+L10+K10+J10+I10 -> 272651.5
B11: NR8 conveyor | F11: =+G11/2 -> 7 | G11: 14 | H11: 1 | I11: =+G11*Sheet1!$E$2 -> 105378 | J11: =+(Sheet1!$E$5+Sheet1!$E$6)*G11 -> 5810 | K11: =+(Sheet1!$E$7+Sheet1!$E$8)*G11 -> 7983.5 | L11: =+Sheet1!$E$4*H11 -> 20480 | M11: 11 | N11: =+M11*Sheet1!$C$13 -> 146300 | O11: =+M11*Sheet1!$C$12 -> 24200 | P11: =+N11+L11+K11+J11+I11 -> 285951.5
B12: NR9 conveyor | F12: =+G12/2 -> 2 | G12: 4 | H12: 1 | I12: =+G12*Sheet1!$E$2 -> 30108 | J12: =+(Sheet1!$E$5+Sheet1!$E$6)*G12 -> 1660 | K12: =+(Sheet1!$E$7+Sheet1!$E$8)*G12 -> 2281 | L12: =+Sheet1!$E$4*H12 -> 20480 | M12: 12 | N12: =+M12*Sheet1!$C$13 -> 159600 | O12: =+M12*Sheet1!$C$12 -> 26400 | P12: =+N12+L12+K12+J12+I12 -> 214129
B13: NR10 conveyor | F13: =+G13/2 -> 7 | G13: 14 | H13: 1 | I13: =+G13*Sheet1!$E$2 -> 105378 | J13: =+(Sheet1!$E$5+Sheet1!$E$6)*G13 -> 5810 | K13: =+(Sheet1!$E$7+Sheet1!$E$8)*G13 -> 7983.5 | L13: =+Sheet1!$E$4*H13 -> 20480 | M13: 13 | N13: =+M13*Sheet1!$C$13 -> 172900 | O13: =+M13*Sheet1!$C$12 -> 28600 | P13: =+N13+L13+K13+J13+I13 -> 312551.5
B14: NR11 conveyor | F14: =+G14/2 -> 9 | G14: 18 | H14: 1 | I14: =+G14*Sheet1!$E$2 -> 135486 | J14: =+(Sheet1!$E$5+Sheet1!$E$6)*G14 -> 7470 | K14: =+(Sheet1!$E$7+Sheet1!$E$8)*G14 -> 10264.5 | L14: =+Sheet1!$E$4*H14 -> 20480 | M14: 14 | N14: =+M14*Sheet1!$C$13 -> 186200 | O14: =+M14*Sheet1!$C$12 -> 30800 | P14: =+N14+L14+K14+J14+I14 -> 359900.5
B15: ST07 conveyor | F15: =+G15/2 -> 8 | G15: 16 | H15: 1 | I15: =+G15*Sheet1!$E$2 -> 120432 | J15: =+(Sheet1!$E$5+Sheet1!$E$6)*G15 -> 6640 | K15: =+(Sheet1!$E$7+Sheet1!$E$8)*G15 -> 9124 | L15: =+Sheet1!$E$4*H15 -> 20480 | M15: 15 | N15: =+M15*Sheet1!$C$13 -> 199500 | O15: =+M15*Sheet1!$C$12 -> 33000 | P15: =+N15+L15+K15+J15+I15 -> 356176
... B19: LS02 conveyor | F19: =+G19/2 -> 7 | G19: 14 | H19: 1 | I19: =+G19*Sheet1!$E$2 -> 105378 | J19: =+(Sheet1!$E$5+Sheet1!$E$6)*G19 -> 5810 | K19: =+(Sheet1!$E$7+Sheet1!$E$8)*G19 -> 7983.5 | L19: =+Sheet1!$E$4*H19 -> 20480 | M19: 19 | N19: =+M19*Sheet1!$C$13 -> 252700 | O19: =+M19*Sheet1!$C$12 -> 41800 | P19: =+N19+L19+K19+J19+I19 -> 392351.5
N20: TOTAL | P20: =SUM(P2:P19) -> 5187558.5
N21: ONCE OFF
N22: Travel | P22: =+Sheet1!$C$11*4 -> 66048
N23: Initial setup | P23: =+Sheet1!$C$10*4 -> 38400
M25: N2 | N25: GRAND TOTAL | P25: =+P20+P22+P23 -> 5292006.5
B28: N3 | F28: # Pulleys | G28: # Sensors | H28: # Gateways | I28: Sensor cost | J28: Base & Spacer | K28: Consumables | L28: Gateway | M28: # Days | N28: Labour Cost | O28: Accommodation | P28: Total Parts & Labour
B29: All split bearings on new belt drive pulleys | F29: 7 | G29: 14 | H29: 7 | I29: =+G29*Sheet1!$E$2 -> 105378 | J29: =+(Sheet1!$E$5+Sheet1!$E$6)*G29 -> 5810 | K29: =+(Sheet1!$E$7+Sheet1!$E$8)*G29 -> 7983.5 | L29: =+Sheet1!$E$4*H29 -> 143360 | M29: 7 | N29: =+M29*Sheet1!$C$13 -> 93100 | O29: =+M29*Sheet1!$C$12 -> 15400 | P29: =+N29+L29+K29+J29+I29 -> 355631.5
N30: ONCE OFF
N31: Travel | P31: =+Sheet1!$C$11 -> 16512
N32: Initial setup | P32: =+Sheet1!$C$10 -> 9600
M33: N3 | N33: GRAND TOTAL | P33: =+P32+P31+P29 -> 381743.5
B36: Gloria | F36: # Pulleys | G36: # Sensors | H36: # Gateways | I36: Sensor cost | J36: Base & Spacer | K36: Consumables | L36: Gateway | M36: # Days | N36: Labour Cost | O36: Accommodation | P36: Total Parts & Labour
B37: 1. CV78 | F37: 8 | G37: 16 | H37: 1 | I37: =+G37*Sheet1!$E$2 -> 120432 | J37: =+(Sheet1!$E$5+Sheet1!$E$6)*G37 -> 6640 | K37: =+(Sheet1!$E$7+Sheet1!$E$8)*G37 -> 9124 | L37: =+Sheet1!$E$4*H37 -> 20480 | M37: 7 | N37: =+M37*Sheet1!$C$13 -> 93100 | O37: =+M37*Sheet1!$C$12 -> 15400 | P37: =+N37+L37+K37+J37+I37 -> 249776
B38: 2. CV75 | F38: 9 | G38: 18 | H38: 1 | I38: =+G38*Sheet1!$E$2 -> 135486 | J38: =+(Sheet1!$E$5+Sheet1!$E$6)*G38 -> 7470 | K38: =+(Sheet1!$E$7+Sheet1!$E$8)*G38 -> 10264.5 | L38: =+Sheet1!$E$4*H38 -> 20480 | M38: 7 | N38: =+M38*Sheet1!$C$13 -> 93100 | O38: =+M38*Sheet1!$C$12 -> 15400 | P38: =+N38+L38+K38+J38+I38 -> 266800.5
B39: 3. CV51 | F39: 8 | G39: 16 | H39: 1 | I39: =+G39*Sheet1!$E$2 -> 120432 | J39: =+(Sheet1!$E$5+Sheet1!$E$6)*G39 -> 6640 | K39: =+(Sheet1!$E$7+Sheet1!$E$8)*G39 -> 9124 | L39: =+Sheet1!$E$4*H39 -> 20480 | M39: 7 | N39: =+M39*Sheet1!$C$13 -> 93100 | O39: =+M39*Sheet1!$C$12 -> 15400 | P39: =+N39+L39+K39+J39+I39 -> 249776
B40: 4. CV10 | F40: 1 | G40: 2 | H40: 1 | I40: =+G40*Sheet1!$E$2 -> 15054 | J40: =+(Sheet1!$E$5+Sheet1!$E$6)*G40 -> 830 | K40: =+(Sheet1!$E$7+Sheet1!$E$8)*G40 -> 1140.5 | L40: =+Sheet1!$E$4*H40 -> 20480 | M40: 7 | N40: =+M40*Sheet1!$C$13 -> 93100 | O40: =+M40*Sheet1!$C$12 -> 15400 | P40: =+N40+L40+K40+J40+I40 -> 130604.5
N41: TOTAL | P41: =SUM(P37:P40) -> 896957
N42: ONCE OFF
N43: Travel | P43: =+Sheet1!$C$11*2 -> 33024
N44: Initial setup | P44: =+Sheet1!$C$10*2 -> 19200
M45: Gloria | N45: GRAND TOTAL | P45: =+P44+P43+P40+P37+P38+P39 -> 949181
B50: N3 Current
B51: R3.3m | C51: 13 belts
B52: All UG belts
...
